Workbook

Sheet Main
A1: FLARM Continuous Analyser of Radio Performance Graph
A2: Copy the CARP data into the cell below, including "RFTOP,A…."
A3: RFTOP,A,1048,2045,2669,1978,2914,2608,1923,1961,1812,1240,1536,1839,2327,2057,2149,1775,1865,1974,1858,1306
A29: Note: If the graph appears wrong, check whether the range for each segment has more than 4 characters. If they do, then amendments are necessary on the calcs page to the CSV parse formula

Sheet Calcs
A1: This table generates the graph, do not change this! | H1: This table extracts the segment Range from the CSV string. Note: It assumes the range data is 4 characters, so the CSV parse formula will will need modification if a range has 5 characters
C2: 5000 | D2: 200 | G2: Data field start position --> | H2: 9 | I2: =H2+5 -> 14 | J2: =I2+5 -> 19 | K2: =J2+5 -> 24 | L2: =K2+5 -> 29 | M2: =L2+5 -> 34 | N2: =M2+5 -> 39 | O2: =N2+5 -> 44 | P2: =O2+5 -> 49 | ... AA2: =Z2+5 -> 104
A3: Bearing | B3: Sector-point | C3: Minimum | E3: Range Data | F3: Spokes | G3: Sector number --> | H3: 1 | I3: 2 | J3: 3 | K3: 4 | L3: 5 | M3: 6 | N3: 7 | O3: 8 | P3: 9 | Q3: 10 | R3: 11 | S3: 12 | T3: 13 | U3: 14 | V3: 15 | W3: 16 | X3: 17 | Y3: 18 | Z3: 19 | AA3: 20
A4: 0 | B4: 10 | C4: =C$2 -> 5000 | D4: 0 | E4: =H4 -> 1048 | G4: CSV parse formula is here --> | H4: =VALUE(MID(Main!$A$3,H2,4)) -> 1048 | I4: =VALUE(MID(Main!$A$3,I2,4)) -> 2045 | J4: =VALUE(MID(Main!$A$3,J2,4)) -> 2669 | K4: =VALUE(MID(Main!$A$3,K2,4)) -> 1978 | L4: =VALUE(MID(Main!$A$3,L2,4)) -> 2914 | M4: =VALUE(MID(Main!$A$3,M2,4)) -> 2608 | N4: =VALUE(MID(Main!$A$3,N2,4)) -> 1923 | O4: =VALUE(MID(Main!$A$3,O2,4)) -> 1961 | ... AA4: =VALUE(MID(Main!$A$3,AA2,4)) -> 1306
A5: 1 | B5: 11 | C5: =C$2 -> 5000 | D5: 0 | E5: =H4 -> 1048
A6: 2 | B6: 12 | C6: =C$2 -> 5000 | D6: 0 | E6: =H4 -> 1048
A7: 3 | B7: 13 | C7: =C$2 -> 5000 | D7: 0 | E7: =H4 -> 1048 | H7: How it works
A8: 4 | B8: 14 | C8: =C$2 -> 5000 | D8: 0 | E8: =H4 -> 1048 | H8: CARP returns the maximum received range x100m in 20 azimuth sectors.
A9: 5 | B9: 15 | C9: =C$2 -> 5000 | D9: 0 | E9: =H4 -> 1048 | H9: The radar graph has 20 sectors of 18 degrees. The first sector (straight ahead = sector 1 ) has bearing 351 - 008 degrees.
A10: 6 | B10: 16 | C10: =C$2 -> 5000 | D10: 0 | E10: =H4 -> 1048 | H10: All values for each bearing within the sector are set to the same range
A11: 7 | B11: 17 | C11: =C$2 -> 5000 | D11: 0 | E11: =H4 -> 1048 | H11: The 'Minimum' range is an approximation to the FLARM minimum acceptable range
A12: 8 | B12: 18 | C12: =C$2+($D$2*D12) -> 5000 | D12: 0 | E12: =H4 -> 1048
A13: 9 | B13: 1 | C13: =C$2+($D$2*D13) -> 4800 | D13: -1 | E13: =I4 -> 2045 | F13: 10000
A14: 10 | B14: 2 | C14: =C$2+($D$2*D14) -> 4800 | D14: -1 | E14: =I4 -> 2045
A15: 11 | B15: 3 | C15: =C$2+($D$2*D15) -> 4800 | D15: -1 | E15: =I4 -> 2045
A16: 12 | B16: 4 | C16: =C$2+($D$2*D16) -> 4800 | D16: -1 | E16: =I4 -> 2045
A17: 13 | B17: 5 | C17: =C$2+($D$2*D17) -> 4800 | D17: -1 | E17: =I4 -> 2045
A18: 14 | B18: 6 | C18: =C$2+($D$2*D18) -> 4800 | D18: -1 | E18: =I4 -> 2045
A19: 15 | B19: 7 | C19: =C$2+($D$2*D19) -> 4800 | D19: -1 | E19: =I4 -> 2045
A20: 16 | B20: 8 | C20: =C$2+($D$2*D20) -> 4800 | D20: -1 | E20: =I4 -> 2045
A21: 17 | B21: 9 | C21: =C$2+($D$2*D21) -> 4800 | D21: -1 | E21: =I4 -> 2045
A22: 18 | B22: 10 | C22: =C$2+($D$2*D22) -> 4800 | D22: -1 | E22: =I4 -> 2045
A23: 19 | B23: 11 | C23: =C$2+($D$2*D23) -> 4800 | D23: -1 | E23: =I4 -> 2045
A24: 20 | B24: 12 | C24: =C$2+($D$2*D24) -> 4800 | D24: -1 | E24: =I4 -> 2045
A25: 21 | B25: 13 | C25: =C$2+($D$2*D25) -> 4800 | D25: -1 | E25: =I4 -> 2045
A26: 22 | B26: 14 | C26: =C$2+($D$2*D26) -> 4800 | D26: -1 | E26: =I4 -> 2045
A27: 23 | B27: 15 | C27: =C$2+($D$2*D27) -> 4800 | D27: -1 | E27: =I4 -> 2045
A28: 24 | B28: 16 | C28: =C$2+($D$2*D28) -> 4800 | D28: -1 | E28: =I4 -> 2045
A29: 25 | B29: 17 | C29: =C$2+($D$2*D29) -> 4800 | D29: -1 | E29: =I4 -> 2045
A30: 26 | B30: 18 | C30: =C$2+($D$2*D30) -> 4800 | D30: -1 | E30: =I4 -> 2045
A31: 27 | B31: 1 | C31: =C$2+($D$2*D31) -> 4600 | D31: -2 | E31: =J4 -> 2669 | F31: 10000
A32: 28 | B32: 2 | C32: =C$2+($D$2*D32) -> 4600 | D32: -2 | E32: =J4 -> 2669
A33: 29 | B33: 3 | C33: =C$2+($D$2*D33) -> 4600 | D33: -2 | E33: =J4 -> 2669
A34: 30 | B34: 4 | C34: =C$2+($D$2*D34) -> 4600 | D34: -2 | E34: =J4 -> 2669
A35: 31 | B35: 5 | C35: =C$2+($D$2*D35) -> 4600 | D35: -2 | E35: =J4 -> 2669
A36: 32 | B36: 6 | C36: =C$2+($D$2*D36) -> 4600 | D36: -2 | E36: =J4 -> 2669
A37: 33 | B37: 7 | C37: =C$2+($D$2*D37) -> 4600 | D37: -2 | E37: =J4 -> 2669
A38: 34 | B38: 8 | C38: =C$2+($D$2*D38) -> 4600 | D38: -2 | E38: =J4 -> 2669
A39: 35 | B39: 9 | C39: =C$2+($D$2*D39) -> 4600 | D39: -2 | E39: =J4 -> 2669
A40: 36 | B40: 10 | C40: =C$2+($D$2*D40) -> 4600 | D40: -2 | E40: =J4 -> 2669
...
